Workbook

Sheet Parametros
A1: Parametro | B1: Valor | C1: Nota
A2: intercept | B2: -0.2 | C2: Bias do sigmoid (z = intercept + aw*appeals - bw*barriers)
A3: barrier_weight | B3: 1.1 | C3: Peso multiplicador das barreiras no sigmoid
A4: appeal_weight | B4: 1.4 | C4: Peso multiplicador dos apelos no sigmoid
A6: trust_gate_active | B6: 1 | C6: 1=ativo para ['financial', 'identity', 'security']
A7: risk_gate_active | B7: 1 | C7: 1=ativo para ['financial', 'identity']
A8: value_gate_active | B8: 1 | C8: 1=ativo para ['aesthetic', 'flow']
A10: experiment_id | B10: exp_375a3cc3
A11: experiment_name | B11: delivery com entrega - nova form1
A12: hypothesis | B12: A hipótese “App de delivery com entrega agendada” assume que permitir ao usuário escolher antecipadamente o dia e o horário da entrega aumenta a sensação de controle e conveniência. Ao reduzir incertezas e conflitos de agenda, a entrega agendada melhora a experiência do cliente, estimula pedidos recorrentes e também facilita o planejamento operacional de restaurantes e entregadores.
A13: feature_types | B13: flow, financial, social

Sheet Mecanismos
A1: mecanismo | B1: valor
A2: irreversibility | B2: 0.5
A3: network_effect | B3: 0.5
A4: institutional_trust | B4: 0.25
A5: habit_displacement | B5: 0.5
A6: learning_curve | B6: 0.5
A7: social_visibility | B7: 0.5
A8: intrinsic_value | B8: 0.5
A9: operational_friction | B9: 0
A10: frequency_of_use | B10: 0.5

Sheet Simulacao
A1: synth_id | B1: nome | C1: risk_aversion | D1: social_dependency | E1: institutional_trust_level | F1: habit_plasticity | G1: friction_tolerance | H1: pragmatism | I1: digital_capability | J1: motor_ability | K1: subject_domain | L1: perceived_risk | M1: social_pressure | N1: trust_barrier | O1: habit_resistance | P1: learning_frustration | Q1: friction_burden | R1: motor_barrier | S1: intrinsic_appeal | T1: frequency_value | U1: domain_advantage | V1: network_bonus | W1: z_score | X1: P_base | Y1: trust_gate | Z1: risk_gate | AA1: value_gate | AB1: P(adopted)
A2: 4w0b2a | B2: Agatha Abreu | C2: 0.5005 | D2: 0.4953 | E2: 0.4069 | F2: 0.5954 | G2: 0.6342 | H2: 0.4178 | I2: 0.5272 | J2: 0.8946 | K2: 0.3151 | L2: =1-(1-Mecanismos!B2)*(1-C2) | M2: =Mecanismos!B7*D2 | N2: =Mecanismos!B4*(1-E2) | O2: =Mecanismos!B5*(1-F2) | P2: =Mecanismos!B6*(1-I2) | Q2: =Mecanismos!B9*(1-G2) | R2: =Mecanismos!B9*(1-J2) | S2: =Mecanismos!B8*H2 | T2: =Mecanismos!B10*H2 | U2: =Mecanismos!B8*K2 | V2: =Mecanismos!B3*D2 | W2: =Parametros!B2+Parametros!B4*(S2+T2+U2+V2)-Parametros!B3*(L2+M2+N2+O2+P2+Q2+R2) | X2: =1/(1+EXP(-W2)) | Y2: =IF(Parametros!B6=1,0.15+0.85*(1/(1+EXP(-8*((1-N2)-0.45)))),1) | Z2: =IF(Parametros!B7=1,MAX(0.05,1-L2^1.6),1) | AA2: =IF(Parametros!B8=1,0.2+0.8*(1/(1+EXP(-9*(S2-0.25)))),1) | AB2: =X2*Y2*Z2*AA2
A3: ycuw8b | B3: Agatha Guerra | C3: 0.672 | D3: 0.3535 | E3: 0.6503 | F3: 0.4687 | G3: 0.1713 | H3: 0.391 | I3: 0.293 | J3: 0.7038 | K3: 0.417 | L3: =1-(1-Mecanismos!B2)*(1-C3) | M3: =Mecanismos!B7*D3 | N3: =Mecanismos!B4*(1-E3) | O3: =Mecanismos!B5*(1-F3) | P3: =Mecanismos!B6*(1-I3) | Q3: =Mecanismos!B9*(1-G3) | R3: =Mecanismos!B9*(1-J3) | S3: =Mecanismos!B8*H3 | T3: =Mecanismos!B10*H3 | U3: =Mecanismos!B8*K3 | V3: =Mecanismos!B3*D3 | W3: =Parametros!B2+Parametros!B4*(S3+T3+U3+V3)-Parametros!B3*(L3+M3+N3+O3+P3+Q3+R3) | X3: =1/(1+EXP(-W3)) | Y3: =IF(Parametros!B6=1,0.15+0.85*(1/(1+EXP(-8*((1-N3)-0.45)))),1) | Z3: =IF(Parametros!B7=1,MAX(0.05,1-L3^1.6),1) | AA3: =IF(Parametros!B8=1,0.2+0.8*(1/(1+EXP(-9*(S3-0.25)))),1) | AB3: =X3*Y3*Z3*AA3
A4: mja8fy | B4: Agatha da Luz | C4: 0.667 | D4: 0.5021 | E4: 0.4128 | F4: 0.3794 | G4: 0.7026 | H4: 0.5784 | I4: 0.6464 | J4: 0.8411 | K4: 0.3977 | L4: =1-(1-Mecanismos!B2)*(1-C4) | M4: =Mecanismos!B7*D4 | N4: =Mecanismos!B4*(1-E4) | O4: =Mecanismos!B5*(1-F4) | P4: =Mecanismos!B6*(1-I4) | Q4: =Mecanismos!B9*(1-G4) | R4: =Mecanismos!B9*(1-J4) | S4: =Mecanismos!B8*H4 | T4: =Mecanismos!B10*H4 | U4: =Mecanismos!B8*K4 | V4: =Mecanismos!B3*D4 | W4: =Parametros!B2+Parametros!B4*(S4+T4+U4+V4)-Parametros!B3*(L4+M4+N4+O4+P4+Q4+R4) | X4: =1/(1+EXP(-W4)) | Y4: =IF(Parametros!B6=1,0.15+0.85*(1/(1+EXP(-8*((1-N4)-0.45)))),1) | Z4: =IF(Parametros!B7=1,MAX(0.05,1-L4^1.6),1) | AA4: =IF(Parametros!B8=1,0.2+0.8*(1/(1+EXP(-9*(S4-0.25)))),1) | AB4: =X4*Y4*Z4*AA4
A5: 2vwwqi | B5: Alana Melo | C5: 0.3713 | D5: 0.5632 | E5: 0.3653 | F5: 0.6151 | G5: 0.5162 | H5: 0.6516 | I5: 0.6868 | J5: 0.849 | K5: 0.5913 | L5: =1-(1-Mecanismos!B2)*(1-C5) | M5: =Mecanismos!B7*D5 | N5: =Mecanismos!B4*(1-E5) | O5: =Mecanismos!B5*(1-F5) | P5: =Mecanismos!B6*(1-I5) | Q5: =Mecanismos!B9*(1-G5) | R5: =Mecanismos!B9*(1-J5) | S5: =Mecanismos!B8*H5 | T5: =Mecanismos!B10*H5 | U5: =Mecanismos!B8*K5 | V5: =Mecanismos!B3*D5 | W5: =Parametros!B2+Parametros!B4*(S5+T5+U5+V5)-Parametros!B3*(L5+M5+N5+O5+P5+Q5+R5) | X5: =1/(1+EXP(-W5)) | Y5: =IF(Parametros!B6=1,0.15+0.85*(1/(1+EXP(-8*((1-N5)-0.45)))),1) | Z5: =IF(Parametros!B7=1,MAX(0.05,1-L5^1.6),1) | AA5: =IF(Parametros!B8=1,0.2+0.8*(1/(1+EXP(-9*(S5-0.25)))),1) | AB5: =X5*Y5*Z5*AA5
A6: hiefbg | B6: Alana Mendes | C6: 0.7579 | D6: 0.364 | E6: 0.494 | F6: 0.654 | G6: 0.5418 | H6: 0.5337 | I6: 0.4388 | J6: 0.7873 | K6: 0.5696 | L6: =1-(1-Mecanismos!B2)*(1-C6) | M6: =Mecanismos!B7*D6 | N6: =Mecanismos!B4*(1-E6) | O6: =Mecanismos!B5*(1-F6) | P6: =Mecanismos!B6*(1-I6) | Q6: =Mecanismos!B9*(1-G6) | R6: =Mecanismos!B9*(1-J6) | S6: =Mecanismos!B8*H6 | T6: =Mecanismos!B10*H6 | U6: =Mecanismos!B8*K6 | V6: =Mecanismos!B3*D6 | W6: =Parametros!B2+Parametros!B4*(S6+T6+U6+V6)-Parametros!B3*(L6+M6+N6+O6+P6+Q6+R6) | X6: =1/(1+EXP(-W6)) | Y6: =IF(Parametros!B6=1,0.15+0.85*(1/(1+EXP(-8*((1-N6)-0.45)))),1) | Z6: =IF(Parametros!B7=1,MAX(0.05,1-L6^1.6),1) | AA6: =IF(Parametros!B8=1,0.2+0.8*(1/(1+EXP(-9*(S6-0.25)))),1) | AB6: =X6*Y6*Z6*AA6
A7: kjbp9x | B7: Alana Sampaio | C7: 0.6633 | D7: 0.6004 | E7: 0.8205 | F7: 0.7936 | G7: 0.4981 | H7: 0.4378 | I7: 0.8625 | J7: 0.9478 | K7: 0.811 | L7: =1-(1-Mecanismos!B2)*(1-C7) | M7: =Mecanismos!B7*D7 | N7: =Mecanismos!B4*(1-E7) | O7: =Mecanismos!B5*(1-F7) | P7: =Mecanismos!B6*(1-I7) | Q7: =Mecanismos!B9*(1-G7) | R7: =Mecanismos!B9*(1-J7) | S7: =Mecanismos!B8*H7 | T7: =Mecanismos!B10*H7 | U7: =Mecanismos!B8*K7 | V7: =Mecanismos!B3*D7 | W7: =Parametros!B2+Parametros!B4*(S7+T7+U7+V7)-Parametros!B3*(L7+M7+N7+O7+P7+Q7+R7) | X7: =1/(1+EXP(-W7)) | Y7: =IF(Parametros!B6=1,0.15+0.85*(1/(1+EXP(-8*((1-N7)-0.45)))),1) | Z7: =IF(Parametros!B7=1,MAX(0.05,1-L7^1.6),1) | AA7: =IF(Parametros!B8=1,0.2+0.8*(1/(1+EXP(-9*(S7-0.25)))),1) | AB7: =X7*Y7*Z7*AA7
A8: 1n4il4 | B8: Alexandre Teixeira | C8: 0.3554 | D8: 0.3904 | E8: 0.36 | F8: 0.5608 | G8: 0.5613 | H8: 0.7287 | I8: 0.4539 | J8: 0.8381 | K8: 0.5836 | L8: =1-(1-Mecanismos!B2)*(1-C8) | M8: =Mecanismos!B7*D8 | N8: =Mecanismos!B4*(1-E8) | O8: =Mecanismos!B5*(1-F8) | P8: =Mecanismos!B6*(1-I8) | Q8: =Mecanismos!B9*(1-G8) | R8: =Mecanismos!B9*(1-J8) | S8: =Mecanismos!B8*H8 | T8: =Mecanismos!B10*H8 | U8: =Mecanismos!B8*K8 | V8: =Mecanismos!B3*D8 | W8: =Parametros!B2+Parametros!B4*(S8+T8+U8+V8)-Parametros!B3*(L8+M8+N8+O8+P8+Q8+R8) | X8: =1/(1+EXP(-W8)) | Y8: =IF(Parametros!B6=1,0.15+0.85*(1/(1+EXP(-8*((1-N8)-0.45)))),1) | Z8: =IF(Parametros!B7=1,MAX(0.05,1-L8^1.6),1) | AA8: =IF(Parametros!B8=1,0.2+0.8*(1/(1+EXP(-9*(S8-0.25)))),1) | AB8: =X8*Y8*Z8*AA8
A9: e0yieb | B9: Alexia Andrade | C9: 0.6242 | D9: 0.6683 | E9: 0.745 | F9: 0.4704 | G9: 0.4094 | H9: 0.6267 | I9: 0.5469 | J9: 0.7495 | K9: 0.2266 | L9: =1-(1-Mecanismos!B2)*(1-C9) | M9: =Mecanismos!B7*D9 | N9: =Mecanismos!B4*(1-E9) | O9: =Mecanismos!B5*(1-F9) | P9: =Mecanismos!B6*(1-I9) | Q9: =Mecanismos!B9*(1-G9) | R9: =Mecanismos!B9*(1-J9) | S9: =Mecanismos!B8*H9 | T9: =Mecanismos!B10*H9 | U9: =Mecanismos!B8*K9 | V9: =Mecanismos!B3*D9 | W9: =Parametros!B2+Parametros!B4*(S9+T9+U9+V9)-Parametros!B3*(L9+M9+N9+O9+P9+Q9+R9) | X9: =1/(1+EXP(-W9)) | Y9: =IF(Parametros!B6=1,0.15+0.85*(1/(1+EXP(-8*((1-N9)-0.45)))),1) | Z9: =IF(Parametros!B7=1,MAX(0.05,1-L9^1.6),1) | AA9: =IF(Parametros!B8=1,0.2+0.8*(1/(1+EXP(-9*(S9-0.25)))),1) | AB9: =X9*Y9*Z9*AA9
A10: 4sq5jx | B10: Alexia Leão | C10: 0.8264 | D10: 0.1673 | E10: 0.7268 | F10: 0.6361 | G10: 0.4829 | H10: 0.615 | I10: 0.2892 | J10: 0.5758 | K10: 0.5314 | L10: =1-(1-Mecanismos!B2)*(1-C10) | M10: =Mecanismos!B7*D10 | N10: =Mecanismos!B4*(1-E10) | O10: =Mecanismos!B5*(1-F10) | P10: =Mecanismos!B6*(1-I10) | Q10: =Mecanismos!B9*(1-G10) | R10: =Mecanismos!B9*(1-J10) | S10: =Mecanismos!B8*H10 | T10: =Mecanismos!B10*H10 | U10: =Mecanismos!B8*K10 | V10: =Mecanismos!B3*D10 | W10: =Parametros!B2+Parametros!B4*(S10+T10+U10+V10)-Parametros!B3*(L10+M10+N10+O10+P10+Q10+R10) | X10: =1/(1+EXP(-W10)) | Y10: =IF(Parametros!B6=1,0.15+0.85*(1/(1+EXP(-8*((1-N10)-0.45)))),1) | Z10: =IF(Parametros!B7=1,MAX(0.05,1-L10^1.6),1) | AA10: =IF(Parametros!B8=1,0.2+0.8*(1/(1+EXP(-9*(S10-0.25)))),1) | AB10: =X10*Y10*Z10*AA10
A11: jmrdzk | B11: Alice Viana | C11: 0.6551 | D11: 0.494 | E11: 0.5437 | F11: 0.5328 | G11: 0.4685 | H11: 0.4087 | I11: 0.4094 | J11: 0.4493 | K11: 0.5552 | L11: =1-(1-Mecanismos!B2)*(1-C11) | M11: =Mecanismos!B7*D11 | N11: =Mecanismos!B4*(1-E11) | O11: =Mecanismos!B5*(1-F11) | P11: =Mecanismos!B6*(1-I11) | Q11: =Mecanismos!B9*(1-G11) | R11: =Mecanismos!B9*(1-J11) | S11: =Mecanismos!B8*H11 | T11: =Mecanismos!B10*H11 | U11: =Mecanismos!B8*K11 | V11: =Mecanismos!B3*D11 | W11: =Parametros!B2+Parametros!B4*(S11+T11+U11+V11)-Parametros!B3*(L11+M11+N11+O11+P11+Q11+R11) | X11: =1/(1+EXP(-W11)) | Y11: =IF(Parametros!B6=1,0.15+0.85*(1/(1+EXP(-8*((1-N11)-0.45)))),1) | Z11: =IF(Parametros!B7=1,MAX(0.05,1-L11^1.6),1) | AA11: =IF(Parametros!B8=1,0.2+0.8*(1/(1+EXP(-9*(S11-0.25)))),1) | AB11: =X11*Y11*Z11*AA11
A12: 7f8fws | B12: Alice da Mata | C12: 0.5141 | D12: 0.6296 | E12: 0.4268 | F12: 0.3476 | G12: 0.374 | H12: 0.6985 | I12: 0.4863 | J12: 0.5631 | K12: 0.6764 | L12: =1-(1-Mecanismos!B2)*(1-C12) | M12: =Mecanismos!B7*D12 | N12: =Mecanismos!B4*(1-E12) | O12: =Mecanismos!B5*(1-F12) | P12: =Mecanismos!B6*(1-I12) | Q12: =Mecanismos!B9*(1-G12) | R12: =Mecanismos!B9*(1-J12) | S12: =Mecanismos!B8*H12 | T12: =Mecanismos!B10*H12 | U12: =Mecanismos!B8*K12 | V12: =Mecanismos!B3*D12 | W12: =Parametros!B2+Parametros!B4*(S12+T12+U12+V12)-Parametros!B3*(L12+M12+N12+O12+P12+Q12+R12) | X12: =1/(1+EXP(-W12)) | Y12: =IF(Parametros!B6=1,0.15+0.85*(1/(1+EXP(-8*((1-N12)-0.45)))),1) | Z12: =IF(Parametros!B7=1,MAX(0.05,1-L12^1.6),1) | AA12: =IF(Parametros!B8=1,0.2+0.8*(1/(1+EXP(-9*(S12-0.25)))),1) | AB12: =X12*Y12*Z12*AA12
A13: rowjhd | B13: Amanda Borges | C13: 0.4831 | D13: 0.7473 | E13: 0.7506 | F13: 0.5026 | G13: 0.4954 | H13: 0.1903 | I13: 0.3792 | J13: 0.8039 | K13: 0.6823 | L13: =1-(1-Mecanismos!B2)*(1-C13) | M13: =Mecanismos!B7*D13 | N13: =Mecanismos!B4*(1-E13) | O13: =Mecanismos!B5*(1-F13) | P13: =Mecanismos!B6*(1-I13) | Q13: =Mecanismos!B9*(1-G13) | R13: =Mecanismos!B9*(1-J13) | S13: =Mecanismos!B8*H13 | T13: =Mecanismos!B10*H13 | U13: =Mecanismos!B8*K13 | V13: =Mecanismos!B3*D13 | W13: =Parametros!B2+Parametros!B4*(S13+T13+U13+V13)-Parametros!B3*(L13+M13+N13+O13+P13+Q13+R13) | X13: =1/(1+EXP(-W13)) | Y13: =IF(Parametros!B6=1,0.15+0.85*(1/(1+EXP(-8*((1-N13)-0.45)))),1) | Z13: =IF(Parametros!B7=1,MAX(0.05,1-L13^1.6),1) | AA13: =IF(Parametros!B8=1,0.2+0.8*(1/(1+EXP(-9*(S13-0.25)))),1) | AB13: =X13*Y13*Z13*AA13
A14: 1y2uu5 | B14: Amanda Macedo | C14: 0.5779 | D14: 0.639 | E14: 0.4479 | F14: 0.487 | G14: 0.5453 | H14: 0.8054 | I14: 0.2896 | J14: 0.7511 | K14: 0.3963 | L14: =1-(1-Mecanismos!B2)*(1-C14) | M14: =Mecanismos!B7*D14 | N14: =Mecanismos!B4*(1-E14) | O14: =Mecanismos!B5*(1-F14) | P14: =Mecanismos!B6*(1-I14) | Q14: =Mecanismos!B9*(1-G14) | R14: =Mecanismos!B9*(1-J14) | S14: =Mecanismos!B8*H14 | T14: =Mecanismos!B10*H14 | U14: =Mecanismos!B8*K14 | V14: =Mecanismos!B3*D14 | W14: =Parametros!B2+Parametros!B4*(S14+T14+U14+V14)-Parametros!B3*(L14+M14+N14+O14+P14+Q14+R14) | X14: =1/(1+EXP(-W14)) | Y14: =IF(Parametros!B6=1,0.15+0.85*(1/(1+EXP(-8*((1-N14)-0.45)))),1) | Z14: =IF(Parametros!B7=1,MAX(0.05,1-L14^1.6),1) | AA14: =IF(Parametros!B8=1,0.2+0.8*(1/(1+EXP(-9*(S14-0.25)))),1) | AB14: =X14*Y14*Z14*AA14
A15: yvzwll | B15: Amanda Peixoto | C15: 0.4727 | D15: 0.7343 | E15: 0.3431 | F15: 0.5958 | G15: 0.5342 | H15: 0.3446 | I15: 0.4876 | J15: 0.8244 | K15: 0.4287 | L15: =1-(1-Mecanismos!B2)*(1-C15) | M15: =Mecanismos!B7*D15 | N15: =Mecanismos!B4*(1-E15) | O15: =Mecanismos!B5*(1-F15) | P15: =Mecanismos!B6*(1-I15) | Q15: =Mecanismos!B9*(1-G15) | R15: =Mecanismos!B9*(1-J15) | S15: =Mecanismos!B8*H15 | T15: =Mecanismos!B10*H15 | U15: =Mecanismos!B8*K15 | V15: =Mecanismos!B3*D15 | W15: =Parametros!B2+Parametros!B4*(S15+T15+U15+V15)-Parametros!B3*(L15+M15+N15+O15+P15+Q15+R15) | X15: =1/(1+EXP(-W15)) | Y15: =IF(Parametros!B6=1,0.15+0.85*(1/(1+EXP(-8*((1-N15)-0.45)))),1) | Z15: =IF(Parametros!B7=1,MAX(0.05,1-L15^1.6),1) | AA15: =IF(Parametros!B8=1,0.2+0.8*(1/(1+EXP(-9*(S15-0.25)))),1) | AB15: =X15*Y15*Z15*AA15
A16: fpdnn9 | B16: Ana Barbosa | C16: 0.6177 | D16: 0.4707 | E16: 0.6524 | F16: 0.3185 | G16: 0.1936 | H16: 0.7026 | I16: 0.4452 | J16: 0.2627 | K16: 0.6608 | L16: =1-(1-Mecanismos!B2)*(1-C16) | M16: =Mecanismos!B7*D16 | N16: =Mecanismos!B4*(1-E16) | O16: =Mecanismos!B5*(1-F16) | P16: =Mecanismos!B6*(1-I16) | Q16: =Mecanismos!B9*(1-G16) | R16: =Mecanismos!B9*(1-J16) | S16: =Mecanismos!B8*H16 | T16: =Mecanismos!B10*H16 | U16: =Mecanismos!B8*K16 | V16: =Mecanismos!B3*D16 | W16: =Parametros!B2+Parametros!B4*(S16+T16+U16+V16)-Parametros!B3*(L16+M16+N16+O16+P16+Q16+R16) | X16: =1/(1+EXP(-W16)) | Y16: =IF(Parametros!B6=1,0.15+0.85*(1/(1+EXP(-8*((1-N16)-0.45)))),1) | Z16: =IF(Parametros!B7=1,MAX(0.05,1-L16^1.6),1) | AA16: =IF(Parametros!B8=1,0.2+0.8*(1/(1+EXP(-9*(S16-0.25)))),1) | AB16: =X16*Y16*Z16*AA16
A17: u054is | B17: Ana Clara Cassiano | C17: 0.482 | D17: 0.3428 | E17: 0.4249 | F17: 0.6884 | G17: 0.3907 | H17: 0.554 | I17: 0.377 | J17: 0.834 | K17: 0.2637 | L17: =1-(1-Mecanismos!B2)*(1-C17) | M17: =Mecanismos!B7*D17 | N17: =Mecanismos!B4*(1-E17) | O17: =Mecanismos!B5*(1-F17) | P17: =Mecanismos!B6*(1-I17) | Q17: =Mecanismos!B9*(1-G17) | R17: =Mecanismos!B9*(1-J17) | S17: =Mecanismos!B8*H17 | T17: =Mecanismos!B10*H17 | U17: =Mecanismos!B8*K17 | V17: =Mecanismos!B3*D17 | W17: =Parametros!B2+Parametros!B4*(S17+T17+U17+V17)-Parametros!B3*(L17+M17+N17+O17+P17+Q17+R17) | X17: =1/(1+EXP(-W17)) | Y17: =IF(Parametros!B6=1,0.15+0.85*(1/(1+EXP(-8*((1-N17)-0.45)))),1) | Z17: =IF(Parametros!B7=1,MAX(0.05,1-L17^1.6),1) | AA17: =IF(Parametros!B8=1,0.2+0.8*(1/(1+EXP(-9*(S17-0.25)))),1) | AB17: =X17*Y17*Z17*AA17
A18: xgsu67 | B18: Ana Clara Rios | C18: 0.6802 | D18: 0.6899 | E18: 0.6476 | F18: 0.5962 | G18: 0.7459 | H18: 0.3991 | I18: 0.4314 | J18: 0.8275 | K18: 0.3217 | L18: =1-(1-Mecanismos!B2)*(1-C18) | M18: =Mecanismos!B7*D18 | N18: =Mecanismos!B4*(1-E18) | O18: =Mecanismos!B5*(1-F18) | P18: =Mecanismos!B6*(1-I18) | Q18: =Mecanismos!B9*(1-G18) | R18: =Mecanismos!B9*(1-J18) | S18: =Mecanismos!B8*H18 | T18: =Mecanismos!B10*H18 | U18: =Mecanismos!B8*K18 | V18: =Mecanismos!B3*D18 | W18: =Parametros!B2+Parametros!B4*(S18+T18+U18+V18)-Parametros!B3*(L18+M18+N18+O18+P18+Q18+R18) | X18: =1/(1+EXP(-W18)) | Y18: =IF(Parametros!B6=1,0.15+0.85*(1/(1+EXP(-8*((1-N18)-0.45)))),1) | Z18: =IF(Parametros!B7=1,MAX(0.05,1-L18^1.6),1) | AA18: =IF(Parametros!B8=1,0.2+0.8*(1/(1+EXP(-9*(S18-0.25)))),1) | AB18: =X18*Y18*Z18*AA18
A19: y8qk5p | B19: Ana Clara Sousa | C19: 0.7096 | D19: 0.5046 | E19: 0.4867 | F19: 0.4112 | G19: 0.4019 | H19: 0.5574 | I19: 0.4573 | J19: 0.6935 | K19: 0.6738 | L19: =1-(1-Mecanismos!B2)*(1-C19) | M19: =Mecanismos!B7*D19 | N19: =Mecanismos!B4*(1-E19) | O19: =Mecanismos!B5*(1-F19) | P19: =Mecanismos!B6*(1-I19) | Q19: =Mecanismos!B9*(1-G19) | R19: =Mecanismos!B9*(1-J19) | S19: =Mecanismos!B8*H19 | T19: =Mecanismos!B10*H19 | U19: =Mecanismos!B8*K19 | V19: =Mecanismos!B3*D19 | W19: =Parametros!B2+Parametros!B4*(S19+T19+U19+V19)-Parametros!B3*(L19+M19+N19+O19+P19+Q19+R19) | X19: =1/(1+EXP(-W19)) | Y19: =IF(Parametros!B6=1,0.15+0.85*(1/(1+EXP(-8*((1-N19)-0.45)))),1) | Z19: =IF(Parametros!B7=1,MAX(0.05,1-L19^1.6),1) | AA19: =IF(Parametros!B8=1,0.2+0.8*(1/(1+EXP(-9*(S19-0.25)))),1) | AB19: =X19*Y19*Z19*AA19
A20: fzr0b1 | B20: Ana Julia Fogaça | C20: 0.5371 | D20: 0.2871 | E20: 0.5211 | F20: 0.9073 | G20: 0.4671 | H20: 0.2976 | I20: 0.9482 | J20: 0.847 | K20: 0.7314 | L20: =1-(1-Mecanismos!B2)*(1-C20) | M20: =Mecanismos!B7*D20 | N20: =Mecanismos!B4*(1-E20) | O20: =Mecanismos!B5*(1-F20) | P20: =Mecanismos!B6*(1-I20) | Q20: =Mecanismos!B9*(1-G20) | R20: =Mecanismos!B9*(1-J20) | S20: =Mecanismos!B8*H20 | T20: =Mecanismos!B10*H20 | U20: =Mecanismos!B8*K20 | V20: =Mecanismos!B3*D20 | W20: =Parametros!B2+Parametros!B4*(S20+T20+U20+V20)-Parametros!B3*(L20+M20+N20+O20+P20+Q20+R20) | X20: =1/(1+EXP(-W20)) | Y20: =IF(Parametros!B6=1,0.15+0.85*(1/(1+EXP(-8*((1-N20)-0.45)))),1) | Z20: =IF(Parametros!B7=1,MAX(0.05,1-L20^1.6),1) | AA20: =IF(Parametros!B8=1,0.2+0.8*(1/(1+EXP(-9*(S20-0.25)))),1) | AB20: =X20*Y20*Z20*AA20
A21: qzmdtd | B21: Ana Laura Teixeira | C21: 0.6281 | D21: 0.4908 | E21: 0.5673 | F21: 0.4507 | G21: 0.3665 | H21: 0.6074 | I21: 0.7429 | J21: 0.8382 | K21: 0.3408 | L21: =1-(1-Mecanismos!B2)*(1-C21) | M21: =Mecanismos!B7*D21 | N21: =Mecanismos!B4*(1-E21) | O21: =Mecanismos!B5*(1-F21) | P21: =Mecanismos!B6*(1-I21) | Q21: =Mecanismos!B9*(1-G21) | R21: =Mecanismos!B9*(1-J21) | S21: =Mecanismos!B8*H21 | T21: =Mecanismos!B10*H21 | U21: =Mecanismos!B8*K21 | V21: =Mecanismos!B3*D21 | W21: =Parametros!B2+Parametros!B4*(S21+T21+U21+V21)-Parametros!B3*(L21+M21+N21+O21+P21+Q21+R21) | X21: =1/(1+EXP(-W21)) | Y21: =IF(Parametros!B6=1,0.15+0.85*(1/(1+EXP(-8*((1-N21)-0.45)))),1) | Z21: =IF(Parametros!B7=1,MAX(0.05,1-L21^1.6),1) | AA21: =IF(Parametros!B8=1,0.2+0.8*(1/(1+EXP(-9*(S21-0.25)))),1) | AB21: =X21*Y21*Z21*AA21
A22: bnq4g8 | B22: Ana Laura Vasconcelos | C22: 0.5275 | D22: 0.2379 | E22: 0.2763 | F22: 0.543 | G22: 0.5091 | H22: 0.6506 | I22: 0.6223 | J22: 0.8881 | K22: 0.7897 | L22: =1-(1-Mecanismos!B2)*(1-C22) | M22: =Mecanismos!B7*D22 | N22: =Mecanismos!B4*(1-E22) | O22: =Mecanismos!B5*(1-F22) | P22: =Mecanismos!B6*(1-I22) | Q22: =Mecanismos!B9*(1-G22) | R22: =Mecanismos!B9*(1-J22) | S22: =Mecanismos!B8*H22 | T22: =Mecanismos!B10*H22 | U22: =Mecanismos!B8*K22 | V22: =Mecanismos!B3*D22 | W22: =Parametros!B2+Parametros!B4*(S22+T22+U22+V22)-Parametros!B3*(L22+M22+N22+O22+P22+Q22+R22) | X22: =1/(1+EXP(-W22)) | Y22: =IF(Parametros!B6=1,0.15+0.85*(1/(1+EXP(-8*((1-N22)-0.45)))),1) | Z22: =IF(Parametros!B7=1,MAX(0.05,1-L22^1.6),1) | AA22: =IF(Parametros!B8=1,0.2+0.8*(1/(1+EXP(-9*(S22-0.25)))),1) | AB22: =X22*Y22*Z22*AA22
A23: 3slswy | B23: Ana Laura da Rosa | C23: 0.7673 | D23: 0.291 | E23: 0.6108 | F23: 0.4839 | G23: 0.518 | H23: 0.5109 | I23: 0.4589 | J23: 0.7555 | K23: 0.744 | L23: =1-(1-Mecanismos!B2)*(1-C23) | M23: =Mecanismos!B7*D23 | N23: =Mecanismos!B4*(1-E23) | O23: =Mecanismos!B5*(1-F23) | P23: =Mecanismos!B6*(1-I23) | Q23: =Mecanismos!B9*(1-G23) | R23: =Mecanismos!B9*(1-J23) | S23: =Mecanismos!B8*H23 | T23: =Mecanismos!B10*H23 | U23: =Mecanismos!B8*K23 | V23: =Mecanismos!B3*D23 | W23: =Parametros!B2+Parametros!B4*(S23+T23+U23+V23)-Parametros!B3*(L23+M23+N23+O23+P23+Q23+R23) | X23: =1/(1+EXP(-W23)) | Y23: =IF(Parametros!B6=1,0.15+0.85*(1/(1+EXP(-8*((1-N23)-0.45)))),1) | Z23: =IF(Parametros!B7=1,MAX(0.05,1-L23^1.6),1) | AA23: =IF(Parametros!B8=1,0.2+0.8*(1/(1+EXP(-9*(S23-0.25)))),1) | AB23: =X23*Y23*Z23*AA23
A24: sjao07 | B24: Ana Liz Borges | C24: 0.4846 | D24: 0.0926 | E24: 0.5595 | F24: 0.3968 | G24: 0.4163 | H24: 0.5266 | I24: 0.5485 | J24: 0.9257 | K24: 0.4696 | L24: =1-(1-Mecanismos!B2)*(1-C24) | M24: =Mecanismos!B7*D24 | N24: =Mecanismos!B4*(1-E24) | O24: =Mecanismos!B5*(1-F24) | P24: =Mecanismos!B6*(1-I24) | Q24: =Mecanismos!B9*(1-G24) | R24: =Mecanismos!B9*(1-J24) | S24: =Mecanismos!B8*H24 | T24: =Mecanismos!B10*H24 | U24: =Mecanismos!B8*K24 | V24: =Mecanismos!B3*D24 | W24: =Parametros!B2+Parametros!B4*(S24+T24+U24+V24)-Parametros!B3*(L24+M24+N24+O24+P24+Q24+R24) | X24: =1/(1+EXP(-W24)) | Y24: =IF(Parametros!B6=1,0.15+0.85*(1/(1+EXP(-8*((1-N24)-0.45)))),1) | Z24: =IF(Parametros!B7=1,MAX(0.05,1-L24^1.6),1) | AA24: =IF(Parametros!B8=1,0.2+0.8*(1/(1+EXP(-9*(S24-0.25)))),1) | AB24: =X24*Y24*Z24*AA24
A25: ubeq1i | B25: Ana Lívia Martins | C25: 0.4008 | D25: 0.4217 | E25: 0.6392 | F25: 0.4039 | G25: 0.3616 | H25: 0.5483 | I25: 0.6078 | J25: 0.7788 | K25: 0.8832 | L25: =1-(1-Mecanismos!B2)*(1-C25) | M25: =Mecanismos!B7*D25 | N25: =Mecanismos!B4*(1-E25) | O25: =Mecanismos!B5*(1-F25) | P25: =Mecanismos!B6*(1-I25) | Q25: =Mecanismos!B9*(1-G25) | R25: =Mecanismos!B9*(1-J25) | S25: =Mecanismos!B8*H25 | T25: =Mecanismos!B10*H25 | U25: =Mecanismos!B8*K25 | V25: =Mecanismos!B3*D25 | W25: =Parametros!B2+Parametros!B4*(S25+T25+U25+V25)-Parametros!B3*(L25+M25+N25+O25+P25+Q25+R25) | X25: =1/(1+EXP(-W25)) | Y25: =IF(Parametros!B6=1,0.15+0.85*(1/(1+EXP(-8*((1-N25)-0.45)))),1) | Z25: =IF(Parametros!B7=1,MAX(0.05,1-L25^1.6),1) | AA25: =IF(Parametros!B8=1,0.2+0.8*(1/(1+EXP(-9*(S25-0.25)))),1) | AB25: =X25*Y25*Z25*AA25
A26: gco66u | B26: Ana Lívia Nogueira | C26: 0.6831 | D26: 0.5648 | E26: 0.4168 | F26: 0.3449 | G26: 0.4306 | H26: 0.3484 | I26: 0.6591 | J26: 0.828 | K26: 0.6324 | L26: =1-(1-Mecanismos!B2)*(1-C26) | M26: =Mecanismos!B7*D26 | N26: =Mecanismos!B4*(1-E26) | O26: =Mecanismos!B5*(1-F26) | P26: =Mecanismos!B6*(1-I26) | Q26: =Mecanismos!B9*(1-G26) | R26: =Mecanismos!B9*(1-J26) | S26: =Mecanismos!B8*H26 | T26: =Mecanismos!B10*H26 | U26: =Mecanismos!B8*K26 | V26: =Mecanismos!B3*D26 | W26: =Parametros!B2+Parametros!B4*(S26+T26+U26+V26)-Parametros!B3*(L26+M26+N26+O26+P26+Q26+R26) | X26: =1/(1+EXP(-W26)) | Y26: =IF(Parametros!B6=1,0.15+0.85*(1/(1+EXP(-8*((1-N26)-0.45)))),1) | Z26: =IF(Parametros!B7=1,MAX(0.05,1-L26^1.6),1) | AA26: =IF(Parametros!B8=1,0.2+0.8*(1/(1+EXP(-9*(S26-0.25)))),1) | AB26: =X26*Y26*Z26*AA26
A27: vnl0qe | B27: Ana Rodrigues | C27: 0.5674 | D27: 0.3866 | E27: 0.6072 | F27: 0.4133 | G27: 0.5369 | H27: 0.8358 | I27: 0.3012 | J27: 0.4514 | K27: 0.728 | L27: =1-(1-Mecanismos!B2)*(1-C27) | M27: =Mecanismos!B7*D27 | N27: =Mecanismos!B4*(1-E27) | O27: =Mecanismos!B5*(1-F27) | P27: =Mecanismos!B6*(1-I27) | Q27: =Mecanismos!B9*(1-G27) | R27: =Mecanismos!B9*(1-J27) | S27: =Mecanismos!B8*H27 | T27: =Mecanismos!B10*H27 | U27: =Mecanismos!B8*K27 | V27: =Mecanismos!B3*D27 | W27: =Parametros!B2+Parametros!B4*(S27+T27+U27+V27)-Parametros!B3*(L27+M27+N27+O27+P27+Q27+R27) | X27: =1/(1+EXP(-W27)) | Y27: =IF(Parametros!B6=1,0.15+0.85*(1/(1+EXP(-8*((1-N27)-0.45)))),1) | Z27: =IF(Parametros!B7=1,MAX(0.05,1-L27^1.6),1) | AA27: =IF(Parametros!B8=1,0.2+0.8*(1/(1+EXP(-9*(S27-0.25)))),1) | AB27: =X27*Y27*Z27*AA27
A28: n9nc23 | B28: Ana Silva | C28: 0.7249 | D28: 0.5329 | E28: 0.5652 | F28: 0.7298 | G28: 0.4544 | H28: 0.3764 | I28: 0.6075 | J28: 0.704 | K28: 0.2905 | L28: =1-(1-Mecanismos!B2)*(1-C28) | M28: =Mecanismos!B7*D28 | N28: =Mecanismos!B4*(1-E28) | O28: =Mecanismos!B5*(1-F28) | P28: =Mecanismos!B6*(1-I28) | Q28: =Mecanismos!B9*(1-G28) | R28: =Mecanismos!B9*(1-J28) | S28: =Mecanismos!B8*H28 | T28: =Mecanismos!B10*H28 | U28: =Mecanismos!B8*K28 | V28: =Mecanismos!B3*D28 | W28: =Parametros!B2+Parametros!B4*(S28+T28+U28+V28)-Parametros!B3*(L28+M28+N28+O28+P28+Q28+R28) | X28: =1/(1+EXP(-W28)) | Y28: =IF(Parametros!B6=1,0.15+0.85*(1/(1+EXP(-8*((1-N28)-0.45)))),1) | Z28: =IF(Parametros!B7=1,MAX(0.05,1-L28^1.6),1) | AA28: =IF(Parametros!B8=1,0.2+0.8*(1/(1+EXP(-9*(S28-0.25)))),1) | AB28: =X28*Y28*Z28*AA28
A29: 55u0d2 | B29: Ana Sophia Nascimento | C29: 0.3826 | D29: 0.5293 | E29: 0.5101 | F29: 0.4367 | G29: 0.7156 | H29: 0.7394 | I29: 0.6999 | J29: 0.8958 | K29: 0.6657 | L29: =1-(1-Mecanismos!B2)*(1-C29) | M29: =Mecanismos!B7*D29 | N29: =Mecanismos!B4*(1-E29) | O29: =Mecanismos!B5*(1-F29) | P29: =Mecanismos!B6*(1-I29) | Q29: =Mecanismos!B9*(1-G29) | R29: =Mecanismos!B9*(1-J29) | S29: =Mecanismos!B8*H29 | T29: =Mecanismos!B10*H29 | U29: =Mecanismos!B8*K29 | V29: =Mecanismos!B3*D29 | W29: =Parametros!B2+Parametros!B4*(S29+T29+U29+V29)-Parametros!B3*(L29+M29+N29+O29+P29+Q29+R29) | X29: =1/(1+EXP(-W29)) | Y29: =IF(Parametros!B6=1,0.15+0.85*(1/(1+EXP(-8*((1-N29)-0.45)))),1) | Z29: =IF(Parametros!B7=1,MAX(0.05,1-L29^1.6),1) | AA29: =IF(Parametros!B8=1,0.2+0.8*(1/(1+EXP(-9*(S29-0.25)))),1) | AB29: =X29*Y29*Z29*AA29
A30: tkas9o | B30: Ana Sophia Rocha | C30: 0.5473 | D30: 0.2928 | E30: 0.6952 | F30: 0.4635 | G30: 0.4481 | H30: 0.5276 | I30: 0.6712 | J30: 0.8159 | K30: 0.4069 | L30: =1-(1-Mecanismos!B2)*(1-C30) | M30: =Mecanismos!B7*D30 | N30: =Mecanismos!B4*(1-E30) | O30: =Mecanismos!B5*(1-F30) | P30: =Mecanismos!B6*(1-I30) | Q30: =Mecanismos!B9*(1-G30) | R30: =Mecanismos!B9*(1-J30) | S30: =Mecanismos!B8*H30 | T30: =Mecanismos!B10*H30 | U30: =Mecanismos!B8*K30 | V30: =Mecanismos!B3*D30 | W30: =Parametros!B2+Parametros!B4*(S30+T30+U30+V30)-Parametros!B3*(L30+M30+N30+O30+P30+Q30+R30) | X30: =1/(1+EXP(-W30)) | Y30: =IF(Parametros!B6=1,0.15+0.85*(1/(1+EXP(-8*((1-N30)-0.45)))),1) | Z30: =IF(Parametros!B7=1,MAX(0.05,1-L30^1.6),1) | AA30: =IF(Parametros!B8=1,0.2+0.8*(1/(1+EXP(-9*(S30-0.25)))),1) | AB30: =X30*Y30*Z30*AA30
A31: lnskvf | B31: Ana Sophia Silva | C31: 0.6033 | D31: 0.5706 | E31: 0.5738 | F31: 0.6856 | G31: 0.625 | H31: 0.6358 | I31: 0.737 | J31: 0.8136 | K31: 0.9127 | L31: =1-(1-Mecanismos!B2)*(1-C31) | M31: =Mecanismos!B7*D31 | N31: =Mecanismos!B4*(1-E31) | O31: =Mecanismos!B5*(1-F31) | P31: =Mecanismos!B6*(1-I31) | Q31: =Mecanismos!B9*(1-G31) | R31: =Mecanismos!B9*(1-J31) | S31: =Mecanismos!B8*H31 | T31: =Mecanismos!B10*H31 | U31: =Mecanismos!B8*K31 | V31: =Mecanismos!B3*D31 | W31: =Parametros!B2+Parametros!B4*(S31+T31+U31+V31)-Parametros!B3*(L31+M31+N31+O31+P31+Q31+R31) | X31: =1/(1+EXP(-W31)) | Y31: =IF(Parametros!B6=1,0.15+0.85*(1/(1+EXP(-8*((1-N31)-0.45)))),1) | Z31: =IF(Parametros!B7=1,MAX(0.05,1-L31^1.6),1) | AA31: =IF(Parametros!B8=1,0.2+0.8*(1/(1+EXP(-9*(S31-0.25)))),1) | AB31: =X31*Y31*Z31*AA31
A32: bycjlg | B32: Ana Vitória Leão | C32: 0.3706 | D32: 0.7253 | E32: 0.2394 | F32: 0.653 | G32: 0.6151 | H32: 0.5171 | I32: 0.8533 | J32: 0.8808 | K32: 0.8521 | L32: =1-(1-Mecanismos!B2)*(1-C32) | M32: =Mecanismos!B7*D32 | N32: =Mecanismos!B4*(1-E32) | O32: =Mecanismos!B5*(1-F32) | P32: =Mecanismos!B6*(1-I32) | Q32: =Mecanismos!B9*(1-G32) | R32: =Mecanismos!B9*(1-J32) | S32: =Mecanismos!B8*H32 | T32: =Mecanismos!B10*H32 | U32: =Mecanismos!B8*K32 | V32: =Mecanismos!B3*D32 | W32: =Parametros!B2+Parametros!B4*(S32+T32+U32+V32)-Parametros!B3*(L32+M32+N32+O32+P32+Q32+R32) | X32: =1/(1+EXP(-W32)) | Y32: =IF(Parametros!B6=1,0.15+0.85*(1/(1+EXP(-8*((1-N32)-0.45)))),1) | Z32: =IF(Parametros!B7=1,MAX(0.05,1-L32^1.6),1) | AA32: =IF(Parametros!B8=1,0.2+0.8*(1/(1+EXP(-9*(S32-0.25)))),1) | AB32: =X32*Y32*Z32*AA32
A33: tlv0r3 | B33: Ana Vitória Novais | C33: 0.792 | D33: 0.6549 | E33: 0.5235 | F33: 0.7449 | G33: 0.5798 | H33: 0.4968 | I33: 0.717 | J33: 0.8845 | K33: 0.7549 | L33: =1-(1-Mecanismos!B2)*(1-C33) | M33: =Mecanismos!B7*D33 | N33: =Mecanismos!B4*(1-E33) | O33: =Mecanismos!B5*(1-F33) | P33: =Mecanismos!B6*(1-I33) | Q33: =Mecanismos!B9*(1-G33) | R33: =Mecanismos!B9*(1-J33) | S33: =Mecanismos!B8*H33 | T33: =Mecanismos!B10*H33 | U33: =Mecanismos!B8*K33 | V33: =Mecanismos!B3*D33 | W33: =Parametros!B2+Parametros!B4*(S33+T33+U33+V33)-Parametros!B3*(L33+M33+N33+O33+P33+Q33+R33) | X33: =1/(1+EXP(-W33)) | Y33: =IF(Parametros!B6=1,0.15+0.85*(1/(1+EXP(-8*((1-N33)-0.45)))),1) | Z33: =IF(Parametros!B7=1,MAX(0.05,1-L33^1.6),1) | AA33: =IF(Parametros!B8=1,0.2+0.8*(1/(1+EXP(-9*(S33-0.25)))),1) | AB33: =X33*Y33*Z33*AA33
A34: cefy7g | B34: Anna Liz Cirino | C34: 0.6093 | D34: 0.4317 | E34: 0.3123 | F34: 0.4777 | G34: 0.4084 | H34: 0.7045 | I34: 0.8122 | J34: 0.7806 | K34: 0.5385 | L34: =1-(1-Mecanismos!B2)*(1-C34) | M34: =Mecanismos!B7*D34 | N34: =Mecanismos!B4*(1-E34) | O34: =Mecanismos!B5*(1-F34) | P34: =Mecanismos!B6*(1-I34) | Q34: =Mecanismos!B9*(1-G34) | R34: =Mecanismos!B9*(1-J34) | S34: =Mecanismos!B8*H34 | T34: =Mecanismos!B10*H34 | U34: =Mecanismos!B8*K34 | V34: =Mecanismos!B3*D34 | W34: =Parametros!B2+Parametros!B4*(S34+T34+U34+V34)-Parametros!B3*(L34+M34+N34+O34+P34+Q34+R34) | X34: =1/(1+EXP(-W34)) | Y34: =IF(Parametros!B6=1,0.15+0.85*(1/(1+EXP(-8*((1-N34)-0.45)))),1) | Z34: =IF(Parametros!B7=1,MAX(0.05,1-L34^1.6),1) | AA34: =IF(Parametros!B8=1,0.2+0.8*(1/(1+EXP(-9*(S34-0.25)))),1) | AB34: =X34*Y34*Z34*AA34
A35: 046c56 | B35: Anna Liz Machado | C35: 0.428 | D35: 0.6072 | E35: 0.5755 | F35: 0.6144 | G35: 0.4749 | H35: 0.7059 | I35: 0.8791 | J35: 0.8352 | K35: 0.5581 | L35: =1-(1-Mecanismos!B2)*(1-C35) | M35: =Mecanismos!B7*D35 | N35: =Mecanismos!B4*(1-E35) | O35: =Mecanismos!B5*(1-F35) | P35: =Mecanismos!B6*(1-I35) | Q35: =Mecanismos!B9*(1-G35) | R35: =Mecanismos!B9*(1-J35) | S35: =Mecanismos!B8*H35 | T35: =Mecanismos!B10*H35 | U35: =Mecanismos!B8*K35 | V35: =Mecanismos!B3*D35 | W35: =Parametros!B2+Parametros!B4*(S35+T35+U35+V35)-Parametros!B3*(L35+M35+N35+O35+P35+Q35+R35) | X35: =1/(1+EXP(-W35)) | Y35: =IF(Parametros!B6=1,0.15+0.85*(1/(1+EXP(-8*((1-N35)-0.45)))),1) | Z35: =IF(Parametros!B7=1,MAX(0.05,1-L35^1.6),1) | AA35: =IF(Parametros!B8=1,0.2+0.8*(1/(1+EXP(-9*(S35-0.25)))),1) | AB35: =X35*Y35*Z35*AA35
A36: 7k0knj | B36: Anthony Abreu | C36: 0.5636 | D36: 0.7009 | E36: 0.664 | F36: 0.7736 | G36: 0.5988 | H36: 0.8451 | I36: 0.4493 | J36: 0.8821 | K36: 0.4559 | L36: =1-(1-Mecanismos!B2)*(1-C36) | M36: =Mecanismos!B7*D36 | N36: =Mecanismos!B4*(1-E36) | O36: =Mecanismos!B5*(1-F36) | P36: =Mecanismos!B6*(1-I36) | Q36: =Mecanismos!B9*(1-G36) | R36: =Mecanismos!B9*(1-J36) | S36: =Mecanismos!B8*H36 | T36: =Mecanismos!B10*H36 | U36: =Mecanismos!B8*K36 | V36: =Mecanismos!B3*D36 | W36: =Parametros!B2+Parametros!B4*(S36+T36+U36+V36)-Parametros!B3*(L36+M36+N36+O36+P36+Q36+R36) | X36: =1/(1+EXP(-W36)) | Y36: =IF(Parametros!B6=1,0.15+0.85*(1/(1+EXP(-8*((1-N36)-0.45)))),1) | Z36: =IF(Parametros!B7=1,MAX(0.05,1-L36^1.6),1) | AA36: =IF(Parametros!B8=1,0.2+0.8*(1/(1+EXP(-9*(S36-0.25)))),1) | AB36: =X36*Y36*Z36*AA36
A37: 3xpc10 | B37: Anthony Gabriel Pimenta | C37: 0.8889 | D37: 0.5508 | E37: 0.6847 | F37: 0.4937 | G37: 0.2592 | H37: 0.5793 | I37: 0.3691 | J37: 0.752 | K37: 0.7699 | L37: =1-(1-Mecanismos!B2)*(1-C37) | M37: =Mecanismos!B7*D37 | N37: =Mecanismos!B4*(1-E37) | O37: =Mecanismos!B5*(1-F37) | P37: =Mecanismos!B6*(1-I37) | Q37: =Mecanismos!B9*(1-G37) | R37: =Mecanismos!B9*(1-J37) | S37: =Mecanismos!B8*H37 | T37: =Mecanismos!B10*H37 | U37: =Mecanismos!B8*K37 | V37: =Mecanismos!B3*D37 | W37: =Parametros!B2+Parametros!B4*(S37+T37+U37+V37)-Parametros!B3*(L37+M37+N37+O37+P37+Q37+R37) | X37: =1/(1+EXP(-W37)) | Y37: =IF(Parametros!B6=1,0.15+0.85*(1/(1+EXP(-8*((1-N37)-0.45)))),1) | Z37: =IF(Parametros!B7=1,MAX(0.05,1-L37^1.6),1) | AA37: =IF(Parametros!B8=1,0.2+0.8*(1/(1+EXP(-9*(S37-0.25)))),1) | AB37: =X37*Y37*Z37*AA37
A38: jojhfk | B38: Anthony Gabriel Porto | C38: 0.5141 | D38: 0.4879 | E38: 0.3232 | F38: 0.7076 | G38: 0.6327 | H38: 0.6287 | I38: 0.299 | J38: 0.9349 | K38: 0.5221 | L38: =1-(1-Mecanismos!B2)*(1-C38) | M38: =Mecanismos!B7*D38 | N38: =Mecanismos!B4*(1-E38) | O38: =Mecanismos!B5*(1-F38) | P38: =Mecanismos!B6*(1-I38) | Q38: =Mecanismos!B9*(1-G38) | R38: =Mecanismos!B9*(1-J38) | S38: =Mecanismos!B8*H38 | T38: =Mecanismos!B10*H38 | U38: =Mecanismos!B8*K38 | V38: =Mecanismos!B3*D38 | W38: =Parametros!B2+Parametros!B4*(S38+T38+U38+V38)-Parametros!B3*(L38+M38+N38+O38+P38+Q38+R38) | X38: =1/(1+EXP(-W38)) | Y38: =IF(Parametros!B6=1,0.15+0.85*(1/(1+EXP(-8*((1-N38)-0.45)))),1) | Z38: =IF(Parametros!B7=1,MAX(0.05,1-L38^1.6),1) | AA38: =IF(Parametros!B8=1,0.2+0.8*(1/(1+EXP(-9*(S38-0.25)))),1) | AB38: =X38*Y38*Z38*AA38
A39: tfym8o | B39: Anthony Vieira | C39: 0.5372 | D39: 0.5576 | E39: 0.4255 | F39: 0.3443 | G39: 0.6178 | H39: 0.4644 | I39: 0.5912 | J39: 0.7356 | K39: 0.2946 | L39: =1-(1-Mecanismos!B2)*(1-C39) | M39: =Mecanismos!B7*D39 | N39: =Mecanismos!B4*(1-E39) | O39: =Mecanismos!B5*(1-F39) | P39: =Mecanismos!B6*(1-I39) | Q39: =Mecanismos!B9*(1-G39) | R39: =Mecanismos!B9*(1-J39) | S39: =Mecanismos!B8*H39 | T39: =Mecanismos!B10*H39 | U39: =Mecanismos!B8*K39 | V39: =Mecanismos!B3*D39 | W39: =Parametros!B2+Parametros!B4*(S39+T39+U39+V39)-Parametros!B3*(L39+M39+N39+O39+P39+Q39+R39) | X39: =1/(1+EXP(-W39)) | Y39: =IF(Parametros!B6=1,0.15+0.85*(1/(1+EXP(-8*((1-N39)-0.45)))),1) | Z39: =IF(Parametros!B7=1,MAX(0.05,1-L39^1.6),1) | AA39: =IF(Parametros!B8=1,0.2+0.8*(1/(1+EXP(-9*(S39-0.25)))),1) | AB39: =X39*Y39*Z39*AA39
A40: 2rub73 | B40: Antonella da Cruz | C40: 0.6084 | D40: 0.6544 | E40: 0.7235 | F40: 0.6455 | G40: 0.4353 | H40: 0.5366 | I40: 0.5555 | J40: 0.7694 | K40: 0.2525 | L40: =1-(1-Mecanismos!B2)*(1-C40) | M40: =Mecanismos!B7*D40 | N40: =Mecanismos!B4*(1-E40) | O40: =Mecanismos!B5*(1-F40) | P40: =Mecanismos!B6*(1-I40) | Q40: =Mecanismos!B9*(1-G40) | R40: =Mecanismos!B9*(1-J40) | S40: =Mecanismos!B8*H40 | T40: =Mecanismos!B10*H40 | U40: =Mecanismos!B8*K40 | V40: =Mecanismos!B3*D40 | W40: =Parametros!B2+Parametros!B4*(S40+T40+U40+V40)-Parametros!B3*(L40+M40+N40+O40+P40+Q40+R40) | X40: =1/(1+EXP(-W40)) | Y40: =IF(Parametros!B6=1,0.15+0.85*(1/(1+EXP(-8*((1-N40)-0.45)))),1) | Z40: =IF(Parametros!B7=1,MAX(0.05,1-L40^1.6),1) | AA40: =IF(Parametros!B8=1,0.2+0.8*(1/(1+EXP(-9*(S40-0.25)))),1) | AB40: =X40*Y40*Z40*AA40
...
